{"name": "Email -- @1.1 ", "status": "broken", "statusDetails": {"message": "urllib3.exceptions.MaxRetryError: HTTPConnectionPool(host='127.0.0.1', port=50907): Max retries exceeded with url: /session/9f34aa7173d2a9c5f3b4297c19ffc91c/screenshot (Caused by NewConnectionError('<urllib3.connection.HTTPConnection object at 0x7fbb9e2123d0>: Failed to establish a new connection: [Errno 61] Connection refused'))\n", "trace": "  File \"/Library/Frameworks/Python.framework/Versions/3.8/lib/python3.8/site-packages/behave/runner.py\", line 545, in run_hook\n    self.hooks[name](context, *args)\n  File \"features/environment.py\", line 78, in after_step\n    allure.attach(context.driver.get_screenshot_as_png(),\n  File \"/Library/Frameworks/Python.framework/Versions/3.8/lib/python3.8/site-packages/selenium/webdriver/remote/webdriver.py\", line 1064, in get_screenshot_as_png\n    return base64.b64decode(self.get_screenshot_as_base64().encode('ascii'))\n  File \"/Library/Frameworks/Python.framework/Versions/3.8/lib/python3.8/site-packages/selenium/webdriver/remote/webdriver.py\", line 1074, in get_screenshot_as_base64\n    return self.execute(Command.SCREENSHOT)['value']\n  File \"/Library/Frameworks/Python.framework/Versions/3.8/lib/python3.8/site-packages/selenium/webdriver/remote/webdriver.py\", line 319, in execute\n    response = self.command_executor.execute(driver_command, params)\n  File \"/Library/Frameworks/Python.framework/Versions/3.8/lib/python3.8/site-packages/selenium/webdriver/remote/remote_connection.py\", line 374, in execute\n    return self._request(command_info[0], url, body=data)\n  File \"/Library/Frameworks/Python.framework/Versions/3.8/lib/python3.8/site-packages/selenium/webdriver/remote/remote_connection.py\", line 397, in _request\n    resp = self._conn.request(method, url, body=body, headers=headers)\n  File \"/Library/Frameworks/Python.framework/Versions/3.8/lib/python3.8/site-packages/urllib3/request.py\", line 75, in request\n    return self.request_encode_url(\n  File \"/Library/Frameworks/Python.framework/Versions/3.8/lib/python3.8/site-packages/urllib3/request.py\", line 97, in request_encode_url\n    return self.urlopen(method, url, **extra_kw)\n  File \"/Library/Frameworks/Python.framework/Versions/3.8/lib/python3.8/site-packages/urllib3/poolmanager.py\", line 336, in urlopen\n    response = conn.urlopen(method, u.request_uri, **kw)\n  File \"/Library/Frameworks/Python.framework/Versions/3.8/lib/python3.8/site-packages/urllib3/connectionpool.py\", line 754, in urlopen\n    return self.urlopen(\n  File \"/Library/Frameworks/Python.framework/Versions/3.8/lib/python3.8/site-packages/urllib3/connectionpool.py\", line 754, in urlopen\n    return self.urlopen(\n  File \"/Library/Frameworks/Python.framework/Versions/3.8/lib/python3.8/site-packages/urllib3/connectionpool.py\", line 754, in urlopen\n    return self.urlopen(\n  File \"/Library/Frameworks/Python.framework/Versions/3.8/lib/python3.8/site-packages/urllib3/connectionpool.py\", line 726, in urlopen\n    retries = retries.increment(\n  File \"/Library/Frameworks/Python.framework/Versions/3.8/lib/python3.8/site-packages/urllib3/util/retry.py\", line 439, in increment\n    raise MaxRetryError(_pool, url, error or ResponseError(cause))\n"}, "steps": [{"name": "Given clear time", "status": "passed", "start": 1608634454270, "stop": 1608634454643}, {"name": "When open f.gum24.online page", "status": "broken", "statusDetails": {"message": "urllib3.exceptions.MaxRetryError: HTTPConnectionPool(host='127.0.0.1', port=50907): Max retries exceeded with url: /session/9f34aa7173d2a9c5f3b4297c19ffc91c/screenshot (Caused by NewConnectionError('<urllib3.connection.HTTPConnection object at 0x7fbb9e2123d0>: Failed to establish a new connection: [Errno 61] Connection refused'))\n", "trace": "  File \"/Library/Frameworks/Python.framework/Versions/3.8/lib/python3.8/site-packages/behave/runner.py\", line 545, in run_hook\n    self.hooks[name](context, *args)\n  File \"features/environment.py\", line 78, in after_step\n    allure.attach(context.driver.get_screenshot_as_png(),\n  File \"/Library/Frameworks/Python.framework/Versions/3.8/lib/python3.8/site-packages/selenium/webdriver/remote/webdriver.py\", line 1064, in get_screenshot_as_png\n    return base64.b64decode(self.get_screenshot_as_base64().encode('ascii'))\n  File \"/Library/Frameworks/Python.framework/Versions/3.8/lib/python3.8/site-packages/selenium/webdriver/remote/webdriver.py\", line 1074, in get_screenshot_as_base64\n    return self.execute(Command.SCREENSHOT)['value']\n  File \"/Library/Frameworks/Python.framework/Versions/3.8/lib/python3.8/site-packages/selenium/webdriver/remote/webdriver.py\", line 319, in execute\n    response = self.command_executor.execute(driver_command, params)\n  File \"/Library/Frameworks/Python.framework/Versions/3.8/lib/python3.8/site-packages/selenium/webdriver/remote/remote_connection.py\", line 374, in execute\n    return self._request(command_info[0], url, body=data)\n  File \"/Library/Frameworks/Python.framework/Versions/3.8/lib/python3.8/site-packages/selenium/webdriver/remote/remote_connection.py\", line 397, in _request\n    resp = self._conn.request(method, url, body=body, headers=headers)\n  File \"/Library/Frameworks/Python.framework/Versions/3.8/lib/python3.8/site-packages/urllib3/request.py\", line 75, in request\n    return self.request_encode_url(\n  File \"/Library/Frameworks/Python.framework/Versions/3.8/lib/python3.8/site-packages/urllib3/request.py\", line 97, in request_encode_url\n    return self.urlopen(method, url, **extra_kw)\n  File \"/Library/Frameworks/Python.framework/Versions/3.8/lib/python3.8/site-packages/urllib3/poolmanager.py\", line 336, in urlopen\n    response = conn.urlopen(method, u.request_uri, **kw)\n  File \"/Library/Frameworks/Python.framework/Versions/3.8/lib/python3.8/site-packages/urllib3/connectionpool.py\", line 754, in urlopen\n    return self.urlopen(\n  File \"/Library/Frameworks/Python.framework/Versions/3.8/lib/python3.8/site-packages/urllib3/connectionpool.py\", line 754, in urlopen\n    return self.urlopen(\n  File \"/Library/Frameworks/Python.framework/Versions/3.8/lib/python3.8/site-packages/urllib3/connectionpool.py\", line 754, in urlopen\n    return self.urlopen(\n  File \"/Library/Frameworks/Python.framework/Versions/3.8/lib/python3.8/site-packages/urllib3/connectionpool.py\", line 726, in urlopen\n    retries = retries.increment(\n  File \"/Library/Frameworks/Python.framework/Versions/3.8/lib/python3.8/site-packages/urllib3/util/retry.py\", line 439, in increment\n    raise MaxRetryError(_pool, url, error or ResponseError(cause))\n"}, "start": 1608634454645, "stop": 1608634461593}, {"name": "When clear time", "status": "skipped", "start": 1608634461595, "stop": 1608634461595}, {"name": "When go to confirmation page", "status": "skipped", "start": 1608634461595, "stop": 1608634461595}, {"name": "When calculate time for 'confirmation'", "status": "skipped", "start": 1608634461595, "stop": 1608634461595}, {"name": "When go to cloudpayments page", "status": "skipped", "start": 1608634461596, "stop": 1608634461596}, {"name": "When enter real card details", "status": "skipped", "start": 1608634461596, "stop": 1608634461596}, {"name": "Then I see 3d secure element", "status": "skipped", "start": 1608634461596, "stop": 1608634461596}, {"name": "When calculate time for 'cloudpayments'", "status": "skipped", "start": 1608634461596, "stop": 1608634461596}], "parameters": [{"name": "page_name", "value": "f.gum24.online"}, {"name": "card", "value": "real card"}, {"name": "type", "value": "3d secure"}], "start": 1608634454268, "stop": 1608634461596, "uuid": "0ecb0a06-9eb9-4438-9378-c8084d503f95", "historyId": "c6dfed3eb102db2d6e0447e5687959b3", "fullName": "features/tests/3/cloudpayments6.feature:Email", "labels": [{"name": "severity", "value": "normal"}, {"name": "tag", "value": "validation"}, {"name": "feature", "value": "fitness-online.ru.com"}, {"name": "framework", "value": "behave"}, {"name": "language", "value": "cpython3"}]}