{"name": "Email -- @1.3 ", "status": "broken", "statusDetails": {"message": "urllib3.exceptions.MaxRetryError: HTTPConnectionPool(host='127.0.0.1', port=60119): Max retries exceeded with url: /session/1687c9f6c26923778a1ea40fb6808fc5/screenshot (Caused by NewConnectionError('<urllib3.connection.HTTPConnection object at 0x7fd8eb9427c0>: Failed to establish a new connection: [Errno 61] Connection refused'))\n", "trace": "  File \"/Library/Frameworks/Python.framework/Versions/3.8/lib/python3.8/site-packages/behave/runner.py\", line 545, in run_hook\n    self.hooks[name](context, *args)\n  File \"features/environment.py\", line 73, in after_step\n    allure.attach(context.driver.get_screenshot_as_png(),\n  File \"/Library/Frameworks/Python.framework/Versions/3.8/lib/python3.8/site-packages/selenium/webdriver/remote/webdriver.py\", line 1064, in get_screenshot_as_png\n    return base64.b64decode(self.get_screenshot_as_base64().encode('ascii'))\n  File \"/Library/Frameworks/Python.framework/Versions/3.8/lib/python3.8/site-packages/selenium/webdriver/remote/webdriver.py\", line 1074, in get_screenshot_as_base64\n    return self.execute(Command.SCREENSHOT)['value']\n  File \"/Library/Frameworks/Python.framework/Versions/3.8/lib/python3.8/site-packages/selenium/webdriver/remote/webdriver.py\", line 319, in execute\n    response = self.command_executor.execute(driver_command, params)\n  File \"/Library/Frameworks/Python.framework/Versions/3.8/lib/python3.8/site-packages/selenium/webdriver/remote/remote_connection.py\", line 374, in execute\n    return self._request(command_info[0], url, body=data)\n  File \"/Library/Frameworks/Python.framework/Versions/3.8/lib/python3.8/site-packages/selenium/webdriver/remote/remote_connection.py\", line 397, in _request\n    resp = self._conn.request(method, url, body=body, headers=headers)\n  File \"/Library/Frameworks/Python.framework/Versions/3.8/lib/python3.8/site-packages/urllib3/request.py\", line 75, in request\n    return self.request_encode_url(\n  File \"/Library/Frameworks/Python.framework/Versions/3.8/lib/python3.8/site-packages/urllib3/request.py\", line 97, in request_encode_url\n    return self.urlopen(method, url, **extra_kw)\n  File \"/Library/Frameworks/Python.framework/Versions/3.8/lib/python3.8/site-packages/urllib3/poolmanager.py\", line 336, in urlopen\n    response = conn.urlopen(method, u.request_uri, **kw)\n  File \"/Library/Frameworks/Python.framework/Versions/3.8/lib/python3.8/site-packages/urllib3/connectionpool.py\", line 754, in urlopen\n    return self.urlopen(\n  File \"/Library/Frameworks/Python.framework/Versions/3.8/lib/python3.8/site-packages/urllib3/connectionpool.py\", line 754, in urlopen\n    return self.urlopen(\n  File \"/Library/Frameworks/Python.framework/Versions/3.8/lib/python3.8/site-packages/urllib3/connectionpool.py\", line 754, in urlopen\n    return self.urlopen(\n  File \"/Library/Frameworks/Python.framework/Versions/3.8/lib/python3.8/site-packages/urllib3/connectionpool.py\", line 726, in urlopen\n    retries = retries.increment(\n  File \"/Library/Frameworks/Python.framework/Versions/3.8/lib/python3.8/site-packages/urllib3/util/retry.py\", line 439, in increment\n    raise MaxRetryError(_pool, url, error or ResponseError(cause))\n"}, "steps": [{"name": "Given clear time", "status": "passed", "start": 1608414000050, "stop": 1608414000051}, {"name": "When open home page", "status": "passed", "start": 1608414000051, "stop": 1608414004443}, {"name": "When calculate time for 'home'", "status": "passed", "start": 1608414004444, "stop": 1608414004444}, {"name": "When go to confirmation page", "status": "broken", "statusDetails": {"message": "urllib3.exceptions.MaxRetryError: HTTPConnectionPool(host='127.0.0.1', port=60119): Max retries exceeded with url: /session/1687c9f6c26923778a1ea40fb6808fc5/screenshot (Caused by NewConnectionError('<urllib3.connection.HTTPConnection object at 0x7fd8eb9427c0>: Failed to establish a new connection: [Errno 61] Connection refused'))\n", "trace": "  File \"/Library/Frameworks/Python.framework/Versions/3.8/lib/python3.8/site-packages/behave/runner.py\", line 545, in run_hook\n    self.hooks[name](context, *args)\n  File \"features/environment.py\", line 73, in after_step\n    allure.attach(context.driver.get_screenshot_as_png(),\n  File \"/Library/Frameworks/Python.framework/Versions/3.8/lib/python3.8/site-packages/selenium/webdriver/remote/webdriver.py\", line 1064, in get_screenshot_as_png\n    return base64.b64decode(self.get_screenshot_as_base64().encode('ascii'))\n  File \"/Library/Frameworks/Python.framework/Versions/3.8/lib/python3.8/site-packages/selenium/webdriver/remote/webdriver.py\", line 1074, in get_screenshot_as_base64\n    return self.execute(Command.SCREENSHOT)['value']\n  File \"/Library/Frameworks/Python.framework/Versions/3.8/lib/python3.8/site-packages/selenium/webdriver/remote/webdriver.py\", line 319, in execute\n    response = self.command_executor.execute(driver_command, params)\n  File \"/Library/Frameworks/Python.framework/Versions/3.8/lib/python3.8/site-packages/selenium/webdriver/remote/remote_connection.py\", line 374, in execute\n    return self._request(command_info[0], url, body=data)\n  File \"/Library/Frameworks/Python.framework/Versions/3.8/lib/python3.8/site-packages/selenium/webdriver/remote/remote_connection.py\", line 397, in _request\n    resp = self._conn.request(method, url, body=body, headers=headers)\n  File \"/Library/Frameworks/Python.framework/Versions/3.8/lib/python3.8/site-packages/urllib3/request.py\", line 75, in request\n    return self.request_encode_url(\n  File \"/Library/Frameworks/Python.framework/Versions/3.8/lib/python3.8/site-packages/urllib3/request.py\", line 97, in request_encode_url\n    return self.urlopen(method, url, **extra_kw)\n  File \"/Library/Frameworks/Python.framework/Versions/3.8/lib/python3.8/site-packages/urllib3/poolmanager.py\", line 336, in urlopen\n    response = conn.urlopen(method, u.request_uri, **kw)\n  File \"/Library/Frameworks/Python.framework/Versions/3.8/lib/python3.8/site-packages/urllib3/connectionpool.py\", line 754, in urlopen\n    return self.urlopen(\n  File \"/Library/Frameworks/Python.framework/Versions/3.8/lib/python3.8/site-packages/urllib3/connectionpool.py\", line 754, in urlopen\n    return self.urlopen(\n  File \"/Library/Frameworks/Python.framework/Versions/3.8/lib/python3.8/site-packages/urllib3/connectionpool.py\", line 754, in urlopen\n    return self.urlopen(\n  File \"/Library/Frameworks/Python.framework/Versions/3.8/lib/python3.8/site-packages/urllib3/connectionpool.py\", line 726, in urlopen\n    retries = retries.increment(\n  File \"/Library/Frameworks/Python.framework/Versions/3.8/lib/python3.8/site-packages/urllib3/util/retry.py\", line 439, in increment\n    raise MaxRetryError(_pool, url, error or ResponseError(cause))\n"}, "start": 1608414004444, "stop": 1608414009458}, {"name": "When calculate time for 'confirmation'", "status": "skipped", "start": 1608414009461, "stop": 1608414009461}, {"name": "When go to cloudpayments page", "status": "skipped", "start": 1608414009461, "stop": 1608414009461}, {"name": "When calculate time for 'payment'", "status": "skipped", "start": 1608414009461, "stop": 1608414009461}, {"name": "When enter real card details", "status": "skipped", "start": 1608414009461, "stop": 1608414009461}, {"name": "Then I see 3d secure element", "status": "skipped", "start": 1608414009461, "stop": 1608414009461}, {"name": "When calculate time for 'purchace'", "status": "skipped", "start": 1608414009461, "stop": 1608414009462}, {"name": "When wait for \"1\" sec", "status": "skipped", "start": 1608414009462, "stop": 1608414009462}], "parameters": [{"name": "card_type", "value": "real card"}], "start": 1608414000049, "stop": 1608414009462, "uuid": "889543d4-9e79-463d-804e-72ae2ba64a8d", "historyId": "8e8de934582551c96f2906a39154dd33", "labels": [{"name": "severity", "value": "normal"}, {"name": "tag", "value": "validation"}, {"name": "feature", "value": "Purchase"}, {"name": "framework", "value": "behave"}, {"name": "language", "value": "cpython3"}]}