{"name": "Email -- @1.1 ", "status": "broken", "statusDetails": {"message": "urllib3.exceptions.MaxRetryError: HTTPConnectionPool(host='127.0.0.1', port=60819): Max retries exceeded with url: /session/b712967c7aaafbbf9f4905037534104c/screenshot (Caused by NewConnectionError('<urllib3.connection.HTTPConnection object at 0x7f82b090e1f0>: Failed to establish a new connection: [Errno 61] Connection refused'))\n", "trace": "  File \"/Library/Frameworks/Python.framework/Versions/3.8/lib/python3.8/site-packages/behave/runner.py\", line 545, in run_hook\n    self.hooks[name](context, *args)\n  File \"features/environment.py\", line 73, in after_step\n    allure.attach(context.driver.get_screenshot_as_png(),\n  File \"/Library/Frameworks/Python.framework/Versions/3.8/lib/python3.8/site-packages/selenium/webdriver/remote/webdriver.py\", line 1064, in get_screenshot_as_png\n    return base64.b64decode(self.get_screenshot_as_base64().encode('ascii'))\n  File \"/Library/Frameworks/Python.framework/Versions/3.8/lib/python3.8/site-packages/selenium/webdriver/remote/webdriver.py\", line 1074, in get_screenshot_as_base64\n    return self.execute(Command.SCREENSHOT)['value']\n  File \"/Library/Frameworks/Python.framework/Versions/3.8/lib/python3.8/site-packages/selenium/webdriver/remote/webdriver.py\", line 319, in execute\n    response = self.command_executor.execute(driver_command, params)\n  File \"/Library/Frameworks/Python.framework/Versions/3.8/lib/python3.8/site-packages/selenium/webdriver/remote/remote_connection.py\", line 374, in execute\n    return self._request(command_info[0], url, body=data)\n  File \"/Library/Frameworks/Python.framework/Versions/3.8/lib/python3.8/site-packages/selenium/webdriver/remote/remote_connection.py\", line 397, in _request\n    resp = self._conn.request(method, url, body=body, headers=headers)\n  File \"/Library/Frameworks/Python.framework/Versions/3.8/lib/python3.8/site-packages/urllib3/request.py\", line 75, in request\n    return self.request_encode_url(\n  File \"/Library/Frameworks/Python.framework/Versions/3.8/lib/python3.8/site-packages/urllib3/request.py\", line 97, in request_encode_url\n    return self.urlopen(method, url, **extra_kw)\n  File \"/Library/Frameworks/Python.framework/Versions/3.8/lib/python3.8/site-packages/urllib3/poolmanager.py\", line 336, in urlopen\n    response = conn.urlopen(method, u.request_uri, **kw)\n  File \"/Library/Frameworks/Python.framework/Versions/3.8/lib/python3.8/site-packages/urllib3/connectionpool.py\", line 754, in urlopen\n    return self.urlopen(\n  File \"/Library/Frameworks/Python.framework/Versions/3.8/lib/python3.8/site-packages/urllib3/connectionpool.py\", line 754, in urlopen\n    return self.urlopen(\n  File \"/Library/Frameworks/Python.framework/Versions/3.8/lib/python3.8/site-packages/urllib3/connectionpool.py\", line 754, in urlopen\n    return self.urlopen(\n  File \"/Library/Frameworks/Python.framework/Versions/3.8/lib/python3.8/site-packages/urllib3/connectionpool.py\", line 726, in urlopen\n    retries = retries.increment(\n  File \"/Library/Frameworks/Python.framework/Versions/3.8/lib/python3.8/site-packages/urllib3/util/retry.py\", line 439, in increment\n    raise MaxRetryError(_pool, url, error or ResponseError(cause))\n"}, "steps": [{"name": "Given clear time", "status": "passed", "start": 1608414059780, "stop": 1608414059781}, {"name": "When open home page", "status": "passed", "start": 1608414059782, "stop": 1608414061273}, {"name": "When calculate time for 'home'", "status": "passed", "start": 1608414061274, "stop": 1608414061274}, {"name": "When go to confirmation page", "status": "passed", "start": 1608414061274, "stop": 1608414105333}, {"name": "When calculate time for 'confirmation'", "status": "passed", "start": 1608414105333, "stop": 1608414105333}, {"name": "When go to cloudpayments page", "status": "broken", "statusDetails": {"message": "urllib3.exceptions.MaxRetryError: HTTPConnectionPool(host='127.0.0.1', port=60819): Max retries exceeded with url: /session/b712967c7aaafbbf9f4905037534104c/screenshot (Caused by NewConnectionError('<urllib3.connection.HTTPConnection object at 0x7f82b090e1f0>: Failed to establish a new connection: [Errno 61] Connection refused'))\n", "trace": "  File \"/Library/Frameworks/Python.framework/Versions/3.8/lib/python3.8/site-packages/behave/runner.py\", line 545, in run_hook\n    self.hooks[name](context, *args)\n  File \"features/environment.py\", line 73, in after_step\n    allure.attach(context.driver.get_screenshot_as_png(),\n  File \"/Library/Frameworks/Python.framework/Versions/3.8/lib/python3.8/site-packages/selenium/webdriver/remote/webdriver.py\", line 1064, in get_screenshot_as_png\n    return base64.b64decode(self.get_screenshot_as_base64().encode('ascii'))\n  File \"/Library/Frameworks/Python.framework/Versions/3.8/lib/python3.8/site-packages/selenium/webdriver/remote/webdriver.py\", line 1074, in get_screenshot_as_base64\n    return self.execute(Command.SCREENSHOT)['value']\n  File \"/Library/Frameworks/Python.framework/Versions/3.8/lib/python3.8/site-packages/selenium/webdriver/remote/webdriver.py\", line 319, in execute\n    response = self.command_executor.execute(driver_command, params)\n  File \"/Library/Frameworks/Python.framework/Versions/3.8/lib/python3.8/site-packages/selenium/webdriver/remote/remote_connection.py\", line 374, in execute\n    return self._request(command_info[0], url, body=data)\n  File \"/Library/Frameworks/Python.framework/Versions/3.8/lib/python3.8/site-packages/selenium/webdriver/remote/remote_connection.py\", line 397, in _request\n    resp = self._conn.request(method, url, body=body, headers=headers)\n  File \"/Library/Frameworks/Python.framework/Versions/3.8/lib/python3.8/site-packages/urllib3/request.py\", line 75, in request\n    return self.request_encode_url(\n  File \"/Library/Frameworks/Python.framework/Versions/3.8/lib/python3.8/site-packages/urllib3/request.py\", line 97, in request_encode_url\n    return self.urlopen(method, url, **extra_kw)\n  File \"/Library/Frameworks/Python.framework/Versions/3.8/lib/python3.8/site-packages/urllib3/poolmanager.py\", line 336, in urlopen\n    response = conn.urlopen(method, u.request_uri, **kw)\n  File \"/Library/Frameworks/Python.framework/Versions/3.8/lib/python3.8/site-packages/urllib3/connectionpool.py\", line 754, in urlopen\n    return self.urlopen(\n  File \"/Library/Frameworks/Python.framework/Versions/3.8/lib/python3.8/site-packages/urllib3/connectionpool.py\", line 754, in urlopen\n    return self.urlopen(\n  File \"/Library/Frameworks/Python.framework/Versions/3.8/lib/python3.8/site-packages/urllib3/connectionpool.py\", line 754, in urlopen\n    return self.urlopen(\n  File \"/Library/Frameworks/Python.framework/Versions/3.8/lib/python3.8/site-packages/urllib3/connectionpool.py\", line 726, in urlopen\n    retries = retries.increment(\n  File \"/Library/Frameworks/Python.framework/Versions/3.8/lib/python3.8/site-packages/urllib3/util/retry.py\", line 439, in increment\n    raise MaxRetryError(_pool, url, error or ResponseError(cause))\n"}, "start": 1608414105333, "stop": 1608414133621}, {"name": "When calculate time for 'payment'", "status": "skipped", "start": 1608414133624, "stop": 1608414133624}, {"name": "When enter fake card details", "status": "skipped", "start": 1608414133625, "stop": 1608414133625}, {"name": "Then I see 3d secure element", "status": "skipped", "start": 1608414133625, "stop": 1608414133625}, {"name": "When calculate time for 'purchace'", "status": "skipped", "start": 1608414133625, "stop": 1608414133625}, {"name": "When wait for \"1\" sec", "status": "skipped", "start": 1608414133625, "stop": 1608414133625}], "parameters": [{"name": "card_type", "value": "fake card"}], "start": 1608414059777, "stop": 1608414133625, "uuid": "bda845aa-9c1c-487b-831a-16fb40dbc492", "historyId": "200cae7671fa7bea2d72f6cfa113029f", "labels": [{"name": "severity", "value": "normal"}, {"name": "tag", "value": "validation"}, {"name": "feature", "value": "Purchase"}, {"name": "framework", "value": "behave"}, {"name": "language", "value": "cpython3"}]}