{"name": "Email -- @1.2 ", "status": "broken", "statusDetails": {"message": "urllib3.exceptions.MaxRetryError: HTTPConnectionPool(host='127.0.0.1', port=60122): Max retries exceeded with url: /session/79278fb0f6cd88eaedfa7b5a85583996/screenshot (Caused by NewConnectionError('<urllib3.connection.HTTPConnection object at 0x7fc4408f2be0>: Failed to establish a new connection: [Errno 61] Connection refused'))\n", "trace": "  File \"/Library/Frameworks/Python.framework/Versions/3.8/lib/python3.8/site-packages/behave/runner.py\", line 545, in run_hook\n    self.hooks[name](context, *args)\n  File \"features/environment.py\", line 73, in after_step\n    allure.attach(context.driver.get_screenshot_as_png(),\n  File \"/Library/Frameworks/Python.framework/Versions/3.8/lib/python3.8/site-packages/selenium/webdriver/remote/webdriver.py\", line 1064, in get_screenshot_as_png\n    return base64.b64decode(self.get_screenshot_as_base64().encode('ascii'))\n  File \"/Library/Frameworks/Python.framework/Versions/3.8/lib/python3.8/site-packages/selenium/webdriver/remote/webdriver.py\", line 1074, in get_screenshot_as_base64\n    return self.execute(Command.SCREENSHOT)['value']\n  File \"/Library/Frameworks/Python.framework/Versions/3.8/lib/python3.8/site-packages/selenium/webdriver/remote/webdriver.py\", line 319, in execute\n    response = self.command_executor.execute(driver_command, params)\n  File \"/Library/Frameworks/Python.framework/Versions/3.8/lib/python3.8/site-packages/selenium/webdriver/remote/remote_connection.py\", line 374, in execute\n    return self._request(command_info[0], url, body=data)\n  File \"/Library/Frameworks/Python.framework/Versions/3.8/lib/python3.8/site-packages/selenium/webdriver/remote/remote_connection.py\", line 397, in _request\n    resp = self._conn.request(method, url, body=body, headers=headers)\n  File \"/Library/Frameworks/Python.framework/Versions/3.8/lib/python3.8/site-packages/urllib3/request.py\", line 75, in request\n    return self.request_encode_url(\n  File \"/Library/Frameworks/Python.framework/Versions/3.8/lib/python3.8/site-packages/urllib3/request.py\", line 97, in request_encode_url\n    return self.urlopen(method, url, **extra_kw)\n  File \"/Library/Frameworks/Python.framework/Versions/3.8/lib/python3.8/site-packages/urllib3/poolmanager.py\", line 336, in urlopen\n    response = conn.urlopen(method, u.request_uri, **kw)\n  File \"/Library/Frameworks/Python.framework/Versions/3.8/lib/python3.8/site-packages/urllib3/connectionpool.py\", line 754, in urlopen\n    return self.urlopen(\n  File \"/Library/Frameworks/Python.framework/Versions/3.8/lib/python3.8/site-packages/urllib3/connectionpool.py\", line 754, in urlopen\n    return self.urlopen(\n  File \"/Library/Frameworks/Python.framework/Versions/3.8/lib/python3.8/site-packages/urllib3/connectionpool.py\", line 754, in urlopen\n    return self.urlopen(\n  File \"/Library/Frameworks/Python.framework/Versions/3.8/lib/python3.8/site-packages/urllib3/connectionpool.py\", line 726, in urlopen\n    retries = retries.increment(\n  File \"/Library/Frameworks/Python.framework/Versions/3.8/lib/python3.8/site-packages/urllib3/util/retry.py\", line 439, in increment\n    raise MaxRetryError(_pool, url, error or ResponseError(cause))\n"}, "steps": [{"name": "Given clear time", "status": "passed", "start": 1608413987779, "stop": 1608413987779}, {"name": "When open home page", "status": "passed", "start": 1608413987779, "stop": 1608413988692}, {"name": "When calculate time for 'home'", "status": "passed", "start": 1608413988692, "stop": 1608413988693}, {"name": "When go to confirmation page", "status": "passed", "start": 1608413988693, "stop": 1608413997264}, {"name": "When calculate time for 'confirmation'", "status": "passed", "start": 1608413997264, "stop": 1608413997265}, {"name": "When go to cloudpayments page", "status": "passed", "start": 1608413997265, "stop": 1608413997558}, {"name": "When calculate time for 'payment'", "status": "passed", "start": 1608413997558, "stop": 1608413997558}, {"name": "When enter real card details", "status": "passed", "start": 1608413997559, "stop": 1608413999802}, {"name": "Then I see 3d secure element", "status": "broken", "statusDetails": {"message": "urllib3.exceptions.MaxRetryError: HTTPConnectionPool(host='127.0.0.1', port=60122): Max retries exceeded with url: /session/79278fb0f6cd88eaedfa7b5a85583996/screenshot (Caused by NewConnectionError('<urllib3.connection.HTTPConnection object at 0x7fc4408f2be0>: Failed to establish a new connection: [Errno 61] Connection refused'))\n", "trace": "  File \"/Library/Frameworks/Python.framework/Versions/3.8/lib/python3.8/site-packages/behave/runner.py\", line 545, in run_hook\n    self.hooks[name](context, *args)\n  File \"features/environment.py\", line 73, in after_step\n    allure.attach(context.driver.get_screenshot_as_png(),\n  File \"/Library/Frameworks/Python.framework/Versions/3.8/lib/python3.8/site-packages/selenium/webdriver/remote/webdriver.py\", line 1064, in get_screenshot_as_png\n    return base64.b64decode(self.get_screenshot_as_base64().encode('ascii'))\n  File \"/Library/Frameworks/Python.framework/Versions/3.8/lib/python3.8/site-packages/selenium/webdriver/remote/webdriver.py\", line 1074, in get_screenshot_as_base64\n    return self.execute(Command.SCREENSHOT)['value']\n  File \"/Library/Frameworks/Python.framework/Versions/3.8/lib/python3.8/site-packages/selenium/webdriver/remote/webdriver.py\", line 319, in execute\n    response = self.command_executor.execute(driver_command, params)\n  File \"/Library/Frameworks/Python.framework/Versions/3.8/lib/python3.8/site-packages/selenium/webdriver/remote/remote_connection.py\", line 374, in execute\n    return self._request(command_info[0], url, body=data)\n  File \"/Library/Frameworks/Python.framework/Versions/3.8/lib/python3.8/site-packages/selenium/webdriver/remote/remote_connection.py\", line 397, in _request\n    resp = self._conn.request(method, url, body=body, headers=headers)\n  File \"/Library/Frameworks/Python.framework/Versions/3.8/lib/python3.8/site-packages/urllib3/request.py\", line 75, in request\n    return self.request_encode_url(\n  File \"/Library/Frameworks/Python.framework/Versions/3.8/lib/python3.8/site-packages/urllib3/request.py\", line 97, in request_encode_url\n    return self.urlopen(method, url, **extra_kw)\n  File \"/Library/Frameworks/Python.framework/Versions/3.8/lib/python3.8/site-packages/urllib3/poolmanager.py\", line 336, in urlopen\n    response = conn.urlopen(method, u.request_uri, **kw)\n  File \"/Library/Frameworks/Python.framework/Versions/3.8/lib/python3.8/site-packages/urllib3/connectionpool.py\", line 754, in urlopen\n    return self.urlopen(\n  File \"/Library/Frameworks/Python.framework/Versions/3.8/lib/python3.8/site-packages/urllib3/connectionpool.py\", line 754, in urlopen\n    return self.urlopen(\n  File \"/Library/Frameworks/Python.framework/Versions/3.8/lib/python3.8/site-packages/urllib3/connectionpool.py\", line 754, in urlopen\n    return self.urlopen(\n  File \"/Library/Frameworks/Python.framework/Versions/3.8/lib/python3.8/site-packages/urllib3/connectionpool.py\", line 726, in urlopen\n    retries = retries.increment(\n  File \"/Library/Frameworks/Python.framework/Versions/3.8/lib/python3.8/site-packages/urllib3/util/retry.py\", line 439, in increment\n    raise MaxRetryError(_pool, url, error or ResponseError(cause))\n"}, "start": 1608413999802, "stop": 1608414009451}, {"name": "When calculate time for 'purchace'", "status": "skipped", "start": 1608414009455, "stop": 1608414009455}, {"name": "When wait for \"1\" sec", "status": "skipped", "start": 1608414009455, "stop": 1608414009455}], "parameters": [{"name": "card_type", "value": "real card"}], "start": 1608413987777, "stop": 1608414009455, "uuid": "e17af084-d54d-44a7-a44d-295f9b52d064", "historyId": "7e564b3884efe7346c7c67fd4e4524e3", "labels": [{"name": "severity", "value": "normal"}, {"name": "tag", "value": "validation"}, {"name": "feature", "value": "Purchase"}, {"name": "framework", "value": "behave"}, {"name": "language", "value": "cpython3"}]}